<?xml version="1.0"?>

<robot xmlns:xacro="http://ros.org/wiki/xacro">

    <link name="base_link">
        <visual>
            <origin xyz="0 0 0" rpy="0 0 0"/>
            <geometry>
                <box size="0.1 0.1 0.02"/>
            </geometry>
            <material name="">
                <color rgba="0.7 0.7 0.7 1"/>
            </material>
        </visual>
        <collision>
            <origin xyz="0 0 0" rpy="0 0 0"/>
            <geometry>
                <box size="0.1 0.1 0.02"/>
            </geometry>
        </collision>
    </link>

    <link name="link_1">
        <visual>
            <origin xyz="0 0 0" rpy="0 0 0"/>
            <geometry>
                <box size="0.01 0.01 0.1"/>
            </geometry>
            <material name="">
                <color rgba="1 0 0 1"/>
            </material>
        </visual>
        <collision>
            <origin xyz="0 0 0" rpy="0 0 0"/>
            <geometry>
                <box size="0.01 0.01 0.1"/>
            </geometry>
        </collision>
    </link>
    

    <joint name="base_1_joint" type="revolute">
        <origin xyz="0 0 0" rpy="0 0 0"/>
        <parent link="base_link"/>
        <child link="link_1"/>
        <axis xyz="0 0 1" rpy="0 0 0"/>
        <limit lower="-1.57" upper="1.57"/>
    </joint>
    
</robot>