<mujoco model="mono_observer">
  <compiler angle="radian" meshdir="../meshes/"/>

  <asset>
    <mesh name="Base" content_type="model/stl" file="Base.stl"/>
    <mesh name="Cintura" content_type="model/stl" file="Cintura.stl"/>
    <mesh name="Antebrazo" content_type="model/stl" file="Antebrazo.stl"/>
    <mesh name="Camara" content_type="model/stl" file="Camara.stl"/>
  </asset>

  <worldbody>
    <geom type="mesh" contype="0" conaffinity="0" group="1" density="0" rgba="0.7 0.7 0.7 1" mesh="Base"/>
    <geom size="0.03 0.015 0.02" pos="-0.0075 0 0.02" type="box" rgba="0.7 0.7 0.7 1"/>
    <body name="link_1" pos="0 0 0.05">
      <inertial pos="0 0 0" mass="0.02" diaginertia="1 1 1"/>
      <joint name="base_1_joint" pos="0 0 0" axis="0 0 1" range="-3.1415 0" actuatorfrcrange="-30 30"/>
      <geom pos="0 0 -0.05" quat="1 0 0 0" type="mesh" contype="0" conaffinity="0" group="1" density="0" rgba="1 0 0 1" mesh="Cintura"/>
      <geom size="0.015 0.015 0.005" type="box" rgba="1 0 0 1"/>
      <body name="link_2" pos="0 0 0.03" quat="0.707105 0 0.707108 0">
        <inertial pos="0 0 0" mass="0.02" diaginertia="1 1 1"/>
        <joint name="1_2_joint" pos="0 0 0" axis="0 1 0" range="-1.7505 1.7505" actuatorfrcrange="-30 30"/>
        <geom pos="0 0 -0.08" type="mesh" contype="0" conaffinity="0" group="1" density="0" rgba="0 1 0 1" mesh="Antebrazo"/>
        <geom size="0.02 0.015 0.025" pos="0 0 0.01" type="box" rgba="0 1 0 1"/>
        <body name="link_3" pos="0 0 0.071" quat="0.707105 0 0.707108 0">
          <inertial pos="0 0 0" mass="0.02" diaginertia="1 1 1"/>
          <joint name="2_3_joint" pos="0 0 0" axis="0 1 0" range="-1.7505 1.7505" actuatorfrcrange="-30 30"/>
          <geom pos="0 0 -0.15" type="mesh" contype="0" conaffinity="0" group="1" density="0" rgba="0 0 1 1" mesh="Camara"/>
          <geom size="0.02 0.015 0.025" pos="0 0 0.0075" type="box" rgba="0 0 1 1"/>
        </body>
      </body>
    </body>
  </worldbody>
</mujoco>
