<?xml version="1.0" ?>
<!-- =================================================================================== -->
<!-- |    This document was autogenerated by xacro from src/mono_observer_description/urdf/mono_observer_controller.xacro | -->
<!-- |    EDITING THIS FILE BY HAND IS NOT RECOMMENDED                                 | -->
<!-- =================================================================================== -->
<robot name="mono_observer">
  <mujoco>
    <compiler discardvisual="false" meshdir="../meshes/"/>
  </mujoco>
  <link name="base_link">
    <inertial>
      <origin rpy="0 0 0" xyz="0.0 0.0 0.0"/>
      <mass value="0.02"/>
      <inertia ixx="1" ixy="0" ixz="0" iyy="1" iyz="0" izz="1"/>
    </inertial>
    <visual>
      <origin rpy="0 0 0" xyz="0 0 0"/>
      <geometry>
        <mesh filename="package://mono_observer_description/meshes/Base.stl"/>
      </geometry>
      <material name="gray">
        <color rgba="0.7 0.7 0.7 1"/>
      </material>
    </visual>
    <collision>
      <origin rpy="0 0 0" xyz="-0.0075 0 0.02"/>
      <geometry>
        <box size="0.06 0.03 0.04"/>
      </geometry>
    </collision>
  </link>
  <link name="link_1">
    <inertial>
      <origin rpy="0 0 0" xyz="0.0 0.0 0.0"/>
      <mass value="0.02"/>
      <inertia ixx="1" ixy="0" ixz="0" iyy="1" iyz="0" izz="1"/>
    </inertial>
    <visual>
      <origin rpy="0 0 0" xyz="0 0 -0.05"/>
      <geometry>
        <mesh filename="package://mono_observer_description/meshes/Cintura.stl"/>
      </geometry>
      <material name="red">
        <color rgba="1 0 0 1"/>
      </material>
    </visual>
    <collision>
      <origin rpy="0 0 0" xyz="0 0 0"/>
      <geometry>
        <box size="0.03 0.03 0.01"/>
      </geometry>
    </collision>
  </link>
  <link name="link_2">
    <inertial>
      <origin rpy="0 0 0" xyz="0.0 0.0 0.0"/>
      <mass value="0.02"/>
      <inertia ixx="1" ixy="0" ixz="0" iyy="1" iyz="0" izz="1"/>
    </inertial>
    <visual>
      <origin rpy="0 0 0" xyz="0 0 -0.08"/>
      <geometry>
        <mesh filename="package://mono_observer_description/meshes/Antebrazo.stl"/>
      </geometry>
      <material name="green">
        <color rgba="0 1 0 1"/>
      </material>
    </visual>
    <collision>
      <origin rpy="0 0 0" xyz="0 0 0.01"/>
      <geometry>
        <box size="0.04 0.03 0.05"/>
      </geometry>
    </collision>
  </link>
  <link name="link_3">
    <inertial>
      <origin rpy="0 0 0" xyz="0.0 0.0 0.0"/>
      <mass value="0.02"/>
      <inertia ixx="1" ixy="0" ixz="0" iyy="1" iyz="0" izz="1"/>
    </inertial>
    <visual>
      <origin rpy="0 0 0" xyz="0 0 -0.15"/>
      <geometry>
        <mesh filename="package://mono_observer_description/meshes/Camara.stl"/>
      </geometry>
      <material name="blue">
        <color rgba="0 0 1 1"/>
      </material>
    </visual>
    <collision>
      <origin rpy="0 0 0" xyz="0 0 0.0075"/>
      <geometry>
        <box size="0.04 0.03 0.05"/>
      </geometry>
    </collision>
  </link>
  <joint name="base_1_joint" type="revolute">
    <origin rpy="0 0 0" xyz="0 0 0.05"/>
    <parent link="base_link"/>
    <child link="link_1"/>
    <axis rpy="0 0 0" xyz="0 0 1"/>
    <limit effort="30" lower="-3.1415" upper="0" velocity="1.0"/>
  </joint>
  <joint name="1_2_joint" type="revolute">
    <origin rpy="0 1.5708 0" xyz="0 0 0.03"/>
    <parent link="link_1"/>
    <child link="link_2"/>
    <axis rpy="0 0 0" xyz="0 1 0"/>
    <limit effort="30" lower="-3.1415" upper="0" velocity="1.0"/>
  </joint>
  <joint name="2_3_joint" type="revolute">
    <origin rpy="0 1.5708 0" xyz="0 0 0.071"/>
    <parent link="link_2"/>
    <child link="link_3"/>
    <axis rpy="0 0 0" xyz="0 1 0"/>
    <limit effort="30" lower="-3.1415" upper="0" velocity="1.0"/>
  </joint>
  <ros2_control name="MujocoSystem" type="system">
    <hardware>
      <plugin>mujoco_ros2_control/MujocoSystem</plugin>
    </hardware>
    <joint name="base_1_joint">
      <command_interface name="position"/>
      <state_interface name="position"/>
      <state_interface name="velocity"/>
      <state_interface name="effort"/>
    </joint>
    <joint name="1_2_joint">
      <command_interface name="position"/>
      <state_interface name="position"/>
      <state_interface name="velocity"/>
      <state_interface name="effort"/>
    </joint>
    <joint name="2_3_joint">
      <command_interface name="position"/>
      <state_interface name="position"/>
      <state_interface name="velocity"/>
      <state_interface name="effort"/>
    </joint>
  </ros2_control>
  <!--Pluging de control-->
  <plugin filename="libmujoco_system_plugins.so" name="control_plugin">
    <robot_param>robot_description</robot_param>
    <robot_param_node>robot_state_publisher</robot_param_node>
    <parameters>/home/robousr/ROS2Dev/proyectos/mono_observer_ws/install/mono_observer_description/share/mono_observer_description/config/trajectory_controller.yaml</parameters>
  </plugin>
  <!--<xacro:include filename="$(find ${package_name})/urdf/camera_sensor.xacro"/>-->
</robot>
